<?xml version="1.0"?>
<robot name="two_link_arm">

  <!-- ============================================= -->
  <!-- BASE LINK                                     -->
  <!-- This is the fixed base of the robot           -->
  <!-- ============================================= -->
  <link name="base_link">
    <visual>
      <geometry>
        <cylinder radius="0.05" length="0.1" />
      </geometry>
      <material name="grey">
        <color rgba="0.7 0.7 0.7 1" />
      </material>
    </visual>
    <collision>
      <geometry>
        <cylinder radius="0.05" length="0.1" />
      </geometry>
    </collision>
    <inertial>
      <mass value="0.1" />
      <inertia ixx="0.0001" ixy="0.0" ixz="0.0" iyy="0.0001" iyz="0.0" izz="0.0001" />
    </inertial>
  </link>

  <!-- ============================================= -->
  <!-- JOINT 1: Connects base_link to link1          -->
  <!-- ============================================= -->
  <joint name="joint1" type="revolute">
    <parent link="base_link" />
    <child link="link1" />
    <origin xyz="0 0 0.05" rpy="0 0 0" /> <!-- Offset to top of base_link -->
    <axis xyz="0 0 1" /> <!-- Rotation around Z-axis -->
    <limit lower="-1.57" upper="1.57" effort="100" velocity="0.5" />
    <dynamics friction="0.1" damping="0.01" />
  </joint>

  <!-- ============================================= -->
  <!-- LINK 1                                        -->
  <!-- First arm segment                             -->
  <!-- ============================================= -->
  <link name="link1">
    <visual>
      <origin xyz="0 0 0.25" rpy="0 0 0" /> <!-- Visual centered on link, so offset by half length -->
      <geometry>
        <box size="0.05 0.05 0.5" />
      </geometry>
      <material name="blue">
        <color rgba="0 0 0.8 1" />
      </material>
    </visual>
    <collision>
      <origin xyz="0 0 0.25" rpy="0 0 0" />
      <geometry>
        <box size="0.05 0.05 0.5" />
      </geometry>
    </collision>
    <inertial>
      <mass value="0.5" />
      <inertia ixx="0.01" ixy="0.0" ixz="0.0" iyy="0.01" iyz="0.0" izz="0.001" />
    </inertial>
  </link>

  <!-- ============================================= -->
  <!-- JOINT 2: Connects link1 to link2              -->
  <!-- ============================================= -->
  <joint name="joint2" type="revolute">
    <parent link="link1" />
    <child link="link2" />
    <origin xyz="0 0 0.5" rpy="0 0 0" /> <!-- Offset to end of link1 -->
    <axis xyz="0 0 1" /> <!-- Rotation around Z-axis -->
    <limit lower="-1.57" upper="1.57" effort="100" velocity="0.5" />
    <dynamics friction="0.1" damping="0.01" />
  </joint>

  <!-- ============================================= -->
  <!-- LINK 2                                        -->
  <!-- Second arm segment                            -->
  <!-- ============================================= -->
  <link name="link2">
    <visual>
      <origin xyz="0 0 0.25" rpy="0 0 0" />
      <geometry>
        <box size="0.05 0.05 0.5" />
      </geometry>
      <material name="green">
        <color rgba="0 0.8 0 1" />
      </material>
    </visual>
    <collision>
      <origin xyz="0 0 0.25" rpy="0 0 0" />
      <geometry>
        <box size="0.05 0.05 0.5" />
      </geometry>
    </collision>
    <inertial>
      <mass value="0.3" />
      <inertia ixx="0.01" ixy="0.0" ixz="0.0" iyy="0.01" iyz="0.0" izz="0.001" />
    </inertial>
  </link>

</robot>
